<?xml version='1.0'?>

<robot name="robot1" xmlns:xacro="http://www.ros.org/wiki/xacro">
 <xacro:include filename="$(find robot1)/urdf/robot_1.gazebo"/>

  <link name="robot_footprint"></link>

  <joint name="robot_footprint_joint" type="fixed">
    <origin xyz="0 0 0" rpy="0 0 0" />
    <parent link="robot_footprint"/>
    <child link="chassis" />
  </joint>

  <link name='chassis'>
    <pose>0 0 0.1 0 0 0</pose>

    <inertial>
      <mass value="10.0"/>
      <origin xyz="0.0 0 0" rpy=" 0 0 0"/>
      <inertia
          ixx="0.1" ixy="0" ixz="0"
          iyy="0.1" iyz="0"
          izz="0.1"
      />
    </inertial>

    <collision name='collision'>
      <origin xyz="0 0 0" rpy=" 0 0 0"/> 
      <geometry>
        <box size=".5 .25 .05"/>
      </geometry>
    </collision>

    <visual name='chassis_visual'>
      <origin xyz="0 0 0" rpy=" 0 0 0"/>
      <geometry>
        <box size=".5 .25 .05"/>
      </geometry>
    </visual>

  </link>

<gazebo reference="chassis">
    <material>Gazebo/Orange</material>
</gazebo>

<!--left front wheel-->
  <link name='left_front_wheel'>
     <visual name ='left_front_wheel_visual'>
	<origin xyz="0 0 0" rpy="0 1.5707 1.5707"/>
	<geometry>
	   <cylinder radius="0.075" length="0.03"/>
	</geometry>
     </visual>

     <inertial>
      	  <mass value="5.0"/>
          <origin xyz="0.0 0 0" rpy="0 1.5707 1.5707"/>
          <inertia
            ixx="0.1" ixy="0" ixz="0"
            iyy="0.1" iyz="0"
            izz="0.1"
          />
     </inertial>

     <collision name='left_front_wheel_collision'>
           <origin xyz="0 0 0" rpy="0 1.5707 1.5707"/> 
           <geometry>
             <cylinder radius="0.075" length="0.03"/>
           </geometry>
     </collision>
  </link>
	
<gazebo reference="left_front_wheel">
    <material>Gazebo/Green</material>
</gazebo>

<!--right front wheel-->
  <link name='right_front_wheel'>
     <visual name ='right_front_wheel_visual'>
	<origin xyz="0 0 0" rpy="0 1.5707 1.5707"/>
	<geometry>
	   <cylinder radius="0.075" length="0.03"/>
	</geometry>
     </visual>

     <inertial>
      	  <mass value="5.0"/>
          <origin xyz="0.0 0 0" rpy=" 0 1.5707 1.5707"/>
          <inertia
            ixx="0.1" ixy="0" ixz="0"
            iyy="0.1" iyz="0"
            izz="0.1"
          />
     </inertial>

     <collision name='right_front_wheel_collision'>
           <origin xyz="0 0 0" rpy=" 0 1.5707 1.5707"/> 
           <geometry>
             <cylinder radius="0.075" length="0.03"/>
           </geometry>
     </collision>
  </link>

<gazebo reference="right_front_wheel">
    <material>Gazebo/Green</material>
</gazebo>
	
<!--left rear wheel-->
  <link name='left_rear_wheel'>
     <visual name ='left_rear_wheel_visual'>
	<origin xyz="0 0 0" rpy="0 1.5707 1.5707"/>
	<geometry>
	   <cylinder radius="0.075" length="0.03"/>
	</geometry>
     </visual>

     <inertial>
      	  <mass value="5.0"/>
          <origin xyz="0.0 0 0" rpy="0 1.5707 1.5707"/>
          <inertia
            ixx="0.1" ixy="0" ixz="0"
            iyy="0.1" iyz="0"
            izz="0.1"
          />
     </inertial>

     <collision name='left_rear_wheel_collision'>
           <origin xyz="0 0 0" rpy="0 1.5707 1.5707"/> 
           <geometry>
             <cylinder radius="0.075" length="0.03"/>
           </geometry>
     </collision>
  </link>
	
<gazebo reference="left_rear_wheel">
    <material>Gazebo/Green</material>
</gazebo>

<!--right back wheel-->
  <link name='right_rear_wheel'>
     <visual name ='right_rear_wheel_visual'>
	<origin xyz="0 0 0" rpy="0 1.5707 1.5707"/>
	<geometry>
	   <cylinder radius="0.075" length="0.03"/>
	</geometry>
     </visual>

     <inertial>
      	  <mass value="5.0"/>
          <origin xyz="0.0 0 0" rpy=" 0 1.5707 1.5707"/>
          <inertia
            ixx="0.1" ixy="0" ixz="0"
            iyy="0.1" iyz="0"
            izz="0.1"
          />
     </inertial>

     <collision name='right_rear_wheel_collision'>
           <origin xyz="0 0 0" rpy=" 0 1.5707 1.5707"/> 
           <geometry>
             <cylinder radius="0.075" length="0.03"/>
           </geometry>
     </collision>
  </link>

<gazebo reference="right_rear_wheel">
    <material>Gazebo/Green</material>
</gazebo>

<!--left front wheel joint-->
  <joint type="continuous" name="left_front_wheel_hinge">
    <origin xyz="0.2 0.15 0" rpy="0 0 0"/>
    <child link="left_front_wheel"/>
    <parent link="chassis"/>
    <axis xyz="0 1 0" rpy="0 0 0"/>
    <limit effort="10000" velocity="1000"/>
    <dynamics damping="1.0" friction="1.0"/>
  </joint>

<!--right front wheel joint-->
  <joint type="continuous" name="right_front_wheel_hinge">
    <origin xyz="0.2 -0.15 0" rpy="0 0 0"/>
    <child link="right_front_wheel"/>
    <parent link="chassis"/>
    <axis xyz="0 1 0" rpy="0 0 0"/>
    <limit effort="10000" velocity="1000"/>
    <dynamics damping="1.0" friction="1.0"/>
  </joint>

<!--left rear wheel joint-->
  <joint type="continuous" name="left_rear_wheel_hinge">
    <origin xyz="-0.2 0.15 0" rpy="0 0 0"/>
    <child link="left_rear_wheel"/>
    <parent link="chassis"/>
    <axis xyz="0 1 0" rpy="0 0 0"/>
    <limit effort="10000" velocity="1000"/>
    <dynamics damping="1.0" friction="1.0"/>
  </joint>

<!--right rear wheel joint-->
  <joint type="continuous" name="right_rear_wheel_hinge">
    <origin xyz="-0.2 -0.15 0" rpy="0 0 0"/>
    <child link="right_rear_wheel"/>
    <parent link="chassis"/>
    <axis xyz="0 1 0" rpy="0 0 0"/>
    <limit effort="10000" velocity="1000"/>
    <dynamics damping="1.0" friction="1.0"/>
  </joint>


<!--camera-->
  <link name='camera'>
     <visual name ='camera_visual'>
	<geometry>
	   <box size="0.05 0.05 0.05"/>
	</geometry>
     </visual>

     <inertial>
      	  <mass value="0.1"/>
          <origin xyz="0 0 0" rpy=" 0 0 0"/>
	  <box_inertia m="0.1" x="0.05" y="0.05" z="0.05" />
          <inertia
            ixx="1e-6" ixy="0" ixz="0"
            iyy="1e-6" iyz="0"
            izz="1e-6"
          />
     </inertial>

     <collision name='collision'>
           <origin xyz="0 0 0" rpy=" 0 0 0"/> 
           <geometry>
             <box size="0.05 0.05 0.05"/>
           </geometry>
     </collision>
  </link>

<gazebo reference="camera">
    <material>Gazebo/Red</material>
</gazebo>

  <joint type="fixed" name="camera_joint">
    <origin xyz="0.25 0 0" rpy="0 0 0"/>
    <child link="camera"/>
    <parent link="chassis"/>
    <axis xyz="0 1 0" rpy="0 0 0"/>
    <limit effort="10000" velocity="1000"/>
    <dynamics damping="1.0" friction="1.0"/>
  </joint>

<!--lidar-->
  <link name='hokuyo'>
     <visual name ='hokuyo_visual'>
	<geometry>
	   <mesh filename="package://robot1/meshes/hokuyo.dae"/>
	</geometry>
     </visual>

     <inertial>
      	  <mass value="1e-5"/>
          <origin xyz="0 0 0" rpy=" 0 0 0"/>
	  <inertia
            ixx="1e-6" ixy="0" ixz="0"
            iyy="1e-6" iyz="0"
            izz="1e-6"
          />
     </inertial>

     <collision name='collision'>
           <origin xyz="0 0 0" rpy=" 0 0 0"/> 
           <geometry>
             <box size="0.1 0.1 0.1"/>
           </geometry>
     </collision>
  </link>

  <joint type="fixed" name="hokuyo_joint">
    <origin xyz="0.2 0 .05" rpy="0 0 0"/>
    <child link="hokuyo"/>
    <parent link="chassis"/>
    <axis xyz="0 1 0" rpy="0 0 0"/>
    <limit effort="10000" velocity="1000"/>
    <dynamics damping="1.0" friction="1.0"/>
  </joint>

</robot>
